<?xml version="1.0"?>
<robot xmlns:xacro="http://www.ros.org/wiki/xacro" name="tracked_vehicle">

  <xacro:include filename="inertial_macros.xacro" />

  <!-- Materials -->
  <material name="black">
    <color rgba="0.0 0.0 0.0 1.0"/>
  </material>
  <material name="dark_grey">
    <color rgba="0.3 0.3 0.3 1.0"/>
  </material>
  <material name="light_grey">
    <color rgba="0.7 0.7 0.7 1.0"/>
  </material>
  <material name="red">
    <color rgba="0.8 0.0 0.0 1.0"/>
  </material>

  <!-- Base Link -->
  <link name="base_link">
  </link>

  <!-- Chassis Link (Main Body) -->
  <joint name="chassis_joint" type="fixed">
    <parent link="base_link"/>
    <child link="chassis"/>
    <origin xyz="0 0 0.345"/>
  </joint>

  <link name="chassis">
    <visual>
      <origin xyz="0 0 0"/>
      <geometry>
        <box size="1.285 0.355 0.345"/>
      </geometry>
      <material name="dark_grey"/>
    </visual>
    <collision>
      <origin xyz="0 0 0"/>
      <geometry>
        <box size="1.285 0.355 0.345"/>
      </geometry>
    </collision>
    <xacro:inertial_box mass="65.0" x="1.285" y="0.355" z="0.345">
      <origin xyz="0 0 0" rpy="0 0 0"/>
    </xacro:inertial_box>
  </link>

  <!-- Right Track -->
  <joint name="right_track_joint" type="fixed">
    <parent link="base_link"/>
    <child link="right_track"/>
    <origin xyz="0 -0.26 0.12074999999999998"/>
  </joint>

  <link name="right_track">
    <visual>
      <geometry>
        <box size="1.1564999999999999 0.165 0.12074999999999998"/>
      </geometry>
      <material name="black"/>
    </visual>
    <xacro:inertial_box mass="3.0" x="1.1564999999999999" y="0.165" z="0.12074999999999998">
      <origin xyz="0 0 0" rpy="0 0 0"/>
    </xacro:inertial_box>
  </link>

  <!-- Left Track -->
  <joint name="left_track_joint" type="fixed">
    <parent link="base_link"/>
    <child link="left_track"/>
    <origin xyz="0 0.26 0.12074999999999998"/>
  </joint>

  <link name="left_track">
    <visual>
      <geometry>
        <box size="1.1564999999999999 0.165 0.12074999999999998"/>
      </geometry>
      <material name="black"/>
    </visual>
    <xacro:inertial_box mass="3.0" x="1.1564999999999999" y="0.165" z="0.12074999999999998">
      <origin xyz="0 0 0" rpy="0 0 0"/>
    </xacro:inertial_box>
  </link>

  <!-- Front Right Wheel -->
  <joint name="front_right_wheel_joint" type="continuous">
    <parent link="base_link"/>
    <child link="front_right_wheel"/>
    <origin xyz="0.5 -0.26 0.12" rpy="${pi/2} 0 0"/>
    <axis xyz="0 0 -1"/>
  </joint>

  <link name="front_right_wheel">
    <visual>
      <geometry>
        <cylinder radius="0.12" length="0.14"/>
      </geometry>
      <material name="light_grey"/>
    </visual>
    <collision>
      <geometry>
        <cylinder radius="0.12" length="0.14"/>
      </geometry>
      <surface>
        <friction>
          <ode>
            <mu>30</mu>
            <mu2>20</mu2>
          </ode>
        </friction>
      </surface>
    </collision>
    <xacro:inertial_cylinder mass="4.0" length="0.14" radius="0.12">
      <origin xyz="0 0 0" rpy="0 0 0"/>
    </xacro:inertial_cylinder>
  </link>

  <!-- Front Left Wheel -->
  <joint name="front_left_wheel_joint" type="continuous">
    <parent link="base_link"/>
    <child link="front_left_wheel"/>
    <origin xyz="0.5 0.26 0.12" rpy="-${pi/2} 0 0"/>
    <axis xyz="0 0 1"/>
  </joint>

  <link name="front_left_wheel">
    <visual>
      <geometry>
        <cylinder radius="0.12" length="0.14"/>
      </geometry>
      <material name="light_grey"/>
    </visual>
    <collision>
      <geometry>
        <cylinder radius="0.12" length="0.14"/>
      </geometry>
      <surface>
        <friction>
          <ode>
            <mu>30</mu>
            <mu2>20</mu2>
          </ode>
        </friction>
      </surface>
    </collision>
    <xacro:inertial_cylinder mass="4.0" length="0.14" radius="0.12">
      <origin xyz="0 0 0" rpy="0 0 0"/>
    </xacro:inertial_cylinder>
  </link>

  <!-- Center Right Wheel -->
  <joint name="center_right_wheel_joint" type="continuous">
    <parent link="base_link"/>
    <child link="center_right_wheel"/>
    <origin xyz="0.0 -0.26 0.12" rpy="${pi/2} 0 0"/>
    <axis xyz="0 0 -1"/>
  </joint>

  <link name="center_right_wheel">
    <visual>
      <geometry>
        <cylinder radius="0.12" length="0.14"/>
      </geometry>
      <material name="light_grey"/>
    </visual>
    <collision>
      <geometry>
        <cylinder radius="0.12" length="0.14"/>
      </geometry>
      <surface>
        <friction>
          <ode>
            <mu>30</mu>
            <mu2>20</mu2>
          </ode>
        </friction>
      </surface>
    </collision>
    <xacro:inertial_cylinder mass="3.0" length="0.14" radius="0.12">
      <origin xyz="0 0 0" rpy="0 0 0"/>
    </xacro:inertial_cylinder>
  </link>

  <!-- Center Left Wheel -->
  <joint name="center_left_wheel_joint" type="continuous">
    <parent link="base_link"/>
    <child link="center_left_wheel"/>
    <origin xyz="0.0 0.26 0.12" rpy="-${pi/2} 0 0"/>
    <axis xyz="0 0 1"/>
  </joint>

  <link name="center_left_wheel">
    <visual>
      <geometry>
        <cylinder radius="0.12" length="0.14"/>
      </geometry>
      <material name="light_grey"/>
    </visual>
    <collision>
      <geometry>
        <cylinder radius="0.12" length="0.14"/>
      </geometry>
      <surface>
        <friction>
          <ode>
            <mu>30</mu>
            <mu2>20</mu2>
          </ode>
        </friction>
      </surface>
    </collision>
    <xacro:inertial_cylinder mass="3.0" length="0.14" radius="0.12">
      <origin xyz="0 0 0" rpy="0 0 0"/>
    </xacro:inertial_cylinder>
  </link>

  <!-- Rear Right Wheel -->
  <joint name="rear_right_wheel_joint" type="continuous">
    <parent link="base_link"/>
    <child link="rear_right_wheel"/>
    <origin xyz="-0.5 -0.26 0.12" rpy="${pi/2} 0 0"/>
    <axis xyz="0 0 -1"/>
  </joint>

  <link name="rear_right_wheel">
    <visual>
      <geometry>
        <cylinder radius="0.12" length="0.14"/>
      </geometry>
      <material name="light_grey"/>
    </visual>
    <collision>
      <geometry>
        <cylinder radius="0.12" length="0.14"/>
      </geometry>
      <surface>
        <friction>
          <ode>
            <mu>30</mu>
            <mu2>20</mu2>
          </ode>
        </friction>
      </surface>
    </collision>
    <xacro:inertial_cylinder mass="4.0" length="0.14" radius="0.12">
      <origin xyz="0 0 0" rpy="0 0 0"/>
    </xacro:inertial_cylinder>
  </link>

  <!-- Rear Left Wheel -->
  <joint name="rear_left_wheel_joint" type="continuous">
    <parent link="base_link"/>
    <child link="rear_left_wheel"/>
    <origin xyz="-0.5 0.26 0.12" rpy="-${pi/2} 0 0"/>
    <axis xyz="0 0 1"/>
  </joint>

  <link name="rear_left_wheel">
    <visual>
      <geometry>
        <cylinder radius="0.12" length="0.14"/>
      </geometry>
      <material name="light_grey"/>
    </visual>
    <collision>
      <geometry>
        <cylinder radius="0.12" length="0.14"/>
      </geometry>
      <surface>
        <friction>
          <ode>
            <mu>30</mu>
            <mu2>20</mu2>
          </ode>
        </friction>
      </surface>
    </collision>
    <xacro:inertial_cylinder mass="4.0" length="0.14" radius="0.12">
      <origin xyz="0 0 0" rpy="0 0 0"/>
    </xacro:inertial_cylinder>
  </link>

  <!-- Velodyne Lidar -->
  <joint name="velodyne_joint" type="fixed">
    <parent link="chassis"/>
    <child link="velodyne"/>
    <origin xyz="0.4283333333333333 0 0.1925"/>
  </joint>

  <link name="velodyne">
    <visual>
      <geometry>
        <cylinder length="0.05" radius="0.05"/>
      </geometry>
      <material name="red"/>
    </visual>
    <collision>
      <origin xyz="0.015 0 -0.0065"/>
      <geometry>
        <cylinder length="0.0315" radius="0.055"/>
      </geometry>
    </collision>
    <xacro:inertial_cylinder mass="5.0" length="0.05" radius="0.05">
      <origin xyz="0 0 0" rpy="0 0 0"/>
    </xacro:inertial_cylinder>
  </link>

  <!-- IMU -->
  <joint name="imu_joint" type="fixed">
    <parent link="chassis"/>
    <child link="imu_link"/>
    <origin xyz="0.4283333333333333 0 0.1925"/>
  </joint>

  <link name="imu_link"/>

  <!-- Gazebo Parameters for Friction -->
  <gazebo reference="chassis">
    <mu1>2.0</mu1>
    <mu2>2.0</mu2>
  </gazebo>

  <gazebo reference="front_right_wheel">
    <mu1>2.0</mu1>
    <mu2>2.0</mu2>
  </gazebo>

  <gazebo reference="front_left_wheel">
    <mu1>2.0</mu1>
    <mu2>2.0</mu2>
  </gazebo>

  <gazebo reference="center_right_wheel">
    <mu1>15.0</mu1>
    <mu2>15.0</mu2>
  </gazebo>

  <gazebo reference="center_left_wheel">
    <mu1>15.0</mu1>
    <mu2>15.0</mu2>
  </gazebo>

  <gazebo reference="rear_right_wheel">
    <mu1>2.0</mu1>
    <mu2>2.0</mu2>
  </gazebo>

  <gazebo reference="rear_left_wheel">
    <mu1>2.0</mu1>
    <mu2>2.0</mu2>
  </gazebo>

  <gazebo reference="right_track">
    <mu1>0.00001</mu1>
    <mu2>0.00001</mu2>
  </gazebo>

  <gazebo reference="left_track">
    <mu1>0.00001</mu1>
    <mu2>0.00001</mu2>
  </gazebo>

  <!-- IMU Sensor -->
  <gazebo reference="imu_link">
    <sensor name="tb3_imu" type="imu">
      <always_on>true</always_on>
      <update_rate>200</update_rate>
      <imu>
        <angular_velocity>
          <x>
            <noise type="gaussian">
              <mean>0.0</mean>
              <stddev>2e-4</stddev>
            </noise>
          </x>
          <y>
            <noise type="gaussian">
              <mean>0.0</mean>
              <stddev>2e-4</stddev>
            </noise>
          </y>
          <z>
            <noise type="gaussian">
              <mean>0.0</mean>
              <stddev>2e-4</stddev>
            </noise>
          </z>
        </angular_velocity>
        <linear_acceleration>
          <x>
            <noise type="gaussian">
              <mean>0.0</mean>
              <stddev>1.7e-2</stddev>
            </noise>
          </x>
          <y>
            <noise type="gaussian">
              <mean>0.0</mean>
              <stddev>1.7e-2</stddev>
            </noise>
          </y>
          <z>
            <noise type="gaussian">
              <mean>0.0</mean>
              <stddev>1.7e-2</stddev>
            </noise>
          </z>
        </linear_acceleration>
      </imu>
    </sensor>
  </gazebo>

  <!-- Velodyne Lidar -->
  <gazebo reference="velodyne">
    <sensor name="velodyne" type="gpu_lidar">
      <update_rate>10</update_rate>
      <visualize>true</visualize>
      <always_on>true</always_on>
      <gz_frame_id>velodyne</gz_frame_id>
      <topic>velodyne</topic>
      <lidar>
        <scan>
          <horizontal>
            <samples>512</samples>
            <resolution>1</resolution>
            <min_angle>-3.14159265359</min_angle>
            <max_angle>3.14159265359</max_angle>
          </horizontal>
          <vertical>
            <samples>32</samples>
            <resolution>1</resolution>
            <min_angle>-0.55</min_angle>
            <max_angle>0.26</max_angle>
          </vertical>
        </scan>
        <range>
          <min>0.2</min>
          <max>131.0</max>
          <resolution>0.01</resolution>
        </range>
      </lidar>
    </sensor>
  </gazebo>

  <!-- Differential Drive Plugin -->
  <gazebo>
    <plugin filename="gz-sim-diff-drive-system" name="gz::sim::systems::DiffDrive">
      <left_joint>front_left_wheel_joint</left_joint>
      <left_joint>center_left_wheel_joint</left_joint>
      <left_joint>rear_left_wheel_joint</left_joint>
      <right_joint>front_right_wheel_joint</right_joint>
      <right_joint>center_right_wheel_joint</right_joint>
      <right_joint>rear_right_wheel_joint</right_joint>
      <wheel_separation>0.52</wheel_separation>
      <wheel_radius>0.12</wheel_radius>
      <topic>cmd_vel</topic>
      <odom_topic>odom</odom_topic>
      <frame_id>odom</frame_id>
      <tf_topic>/tf</tf_topic>
      <child_frame_id>base_link</child_frame_id>
      <odom_publisher_frequency>100</odom_publisher_frequency>
    </plugin>
  </gazebo>

  <!-- Joint State Publisher -->
  <gazebo>
    <plugin filename="gz-sim-joint-state-publisher-system" name="gz::sim::systems::JointStatePublisher">
      <topic>joint_states</topic>
      <update_rate>30</update_rate>
      <joint_name>front_left_wheel_joint</joint_name>
      <joint_name>front_right_wheel_joint</joint_name>
      <joint_name>center_left_wheel_joint</joint_name>
      <joint_name>center_right_wheel_joint</joint_name>
      <joint_name>rear_left_wheel_joint</joint_name>
      <joint_name>rear_right_wheel_joint</joint_name>
    </plugin>
  </gazebo>

</robot>