<?xml version="1.0" ?>
<!-- =================================================================================== -->
<!-- |    This document was autogenerated by xacro from shredder.urdf.xacro            | -->
<!-- |    EDITING THIS FILE BY HAND IS NOT RECOMMENDED                                 | -->
<!-- =================================================================================== -->
<robot name="tracked_vehicle">
  <!-- Materials -->
  <material name="black">
    <color rgba="0.0 0.0 0.0 1.0"/>
  </material>
  <material name="dark_grey">
    <color rgba="0.3 0.3 0.3 1.0"/>
  </material>
  <material name="light_grey">
    <color rgba="0.7 0.7 0.7 1.0"/>
  </material>
  <material name="red">
    <color rgba="0.8 0.0 0.0 1.0"/>
  </material>
  
  <!-- Base Link (Center of the robot) -->
  <link name="base_link">
    <visual>
      <geometry>
        <box size="1.285 0.355 0.345"/>
      </geometry>
      <material name="dark_grey"/>
      <origin xyz="0 0 0.345"/>
    </visual>
    <collision>
      <geometry>
        <box size="1.285 0.355 0.345"/>
      </geometry>
      <origin xyz="0 0 0.345"/>
    </collision>
    <inertial>
      <mass value="50.0"/>
      <inertia ixx="1.0" ixy="0.0" ixz="0.0" iyy="8.0" iyz="0.0" izz="9.0"/>
      <origin xyz="0 0 0.345"/>
    </inertial>
  </link>

  <!-- Right Track -->
  <link name="right_track_link">
    <visual>
      <geometry>
        <box size="1.1564999999999999 0.165 0.12074999999999998"/>
      </geometry>
      <material name="black"/>
    </visual>
    <inertial>
      <mass value="5.0"/>
      <inertia ixx="0.01" ixy="0.0" ixz="0.0" iyy="0.04" iyz="0.0" izz="0.05"/>
      <origin xyz="0 0 0"/>
    </inertial>
  </link>
  <joint name="right_track_joint" type="fixed">
    <parent link="base_link"/>
    <child link="right_track_link"/>
    <origin xyz="0 -0.26 0.12074999999999998"/>
  </joint>

  <!-- Left Track -->
  <link name="left_track_link">
    <visual>
      <geometry>
        <box size="1.1564999999999999 0.165 0.12074999999999998"/>
      </geometry>
      <material name="black"/>
    </visual>
    <inertial>
      <mass value="5.0"/>
      <inertia ixx="0.01" ixy="0.0" ixz="0.0" iyy="0.04" iyz="0.0" izz="0.05"/>
      <origin xyz="0 0 0"/>
    </inertial>
  </link>
  <joint name="left_track_joint" type="fixed">
    <parent link="base_link"/>
    <child link="left_track_link"/>
    <origin xyz="0 0.26 0.12074999999999998"/>
  </joint>

  <!-- 3 wheels per side, evenly spaced across 1.285m base frame -->
  <!-- Spacing: 0.5m between wheels, positions at -0.5, 0.0, +0.5 -->

  <!-- Front Right Wheel -->
  <link name="front_right_wheel_link">
    <visual>
      <geometry>
        <cylinder length="0.14" radius="0.12"/>
      </geometry>
      <material name="light_grey"/>
      <origin rpy="1.5707963267948966 0 0"/>
    </visual>
    <collision>
      <geometry>
        <cylinder length="0.14" radius="0.12"/>
      </geometry>
      <origin rpy="1.5707963267948966 0 0"/>
      <surface>
        <friction>
          <ode>
            <mu>30</mu>
            <mu2>20</mu2>
          </ode>
        </friction>
      </surface>
    </collision>
    <inertial>
      <mass value="2.0"/>
      <inertia ixx="0.0005" ixy="0.0" ixz="0.0" iyy="0.0005" iyz="0.0" izz="0.0003"/>
      <origin xyz="0 0 0"/>
    </inertial>
  </link>
  <joint name="front_right_wheel_joint" type="continuous">
    <parent link="base_link"/>
    <child link="front_right_wheel_link"/>
    <origin xyz="0.5 -0.26 0.12"/>
    <axis xyz="0 1 0"/>
  </joint>

  <!-- Front Left Wheel -->
  <link name="front_left_wheel_link">
    <visual>
      <geometry>
        <cylinder length="0.14" radius="0.12"/>
      </geometry>
      <material name="light_grey"/>
      <origin rpy="1.5707963267948966 0 0"/>
    </visual>
    <collision>
      <geometry>
        <cylinder length="0.14" radius="0.12"/>
      </geometry>
      <origin rpy="1.5707963267948966 0 0"/>
      <surface>
        <friction>
          <ode>
            <mu>30</mu>
            <mu2>20</mu2>
          </ode>
        </friction>
      </surface>
    </collision>
    <inertial>
      <mass value="2.0"/>
      <inertia ixx="0.0005" ixy="0.0" ixz="0.0" iyy="0.0005" iyz="0.0" izz="0.0003"/>
      <origin xyz="0 0 0"/>
    </inertial>
  </link>
  <joint name="front_left_wheel_joint" type="continuous">
    <parent link="base_link"/>
    <child link="front_left_wheel_link"/>
    <origin xyz="0.5 0.26 0.12"/>
    <axis xyz="0 1 0"/>
  </joint>

  <!-- Center Right Wheel -->
  <link name="center_right_wheel_link">
    <visual>
      <geometry>
        <cylinder length="0.14" radius="0.12"/>
      </geometry>
      <material name="light_grey"/>
      <origin rpy="1.5707963267948966 0 0"/>
    </visual>
    <collision>
      <geometry>
        <cylinder length="0.14" radius="0.12"/>
      </geometry>
      <origin rpy="1.5707963267948966 0 0"/>
      <surface>
        <friction>
          <ode>
            <mu>30</mu>
            <mu2>20</mu2>
          </ode>
        </friction>
      </surface>
    </collision>
    <inertial>
      <mass value="2.0"/>
      <inertia ixx="0.0005" ixy="0.0" ixz="0.0" iyy="0.0005" iyz="0.0" izz="0.0003"/>
      <origin xyz="0 0 0"/>
    </inertial>
  </link>
  <joint name="center_right_wheel_joint" type="continuous">
    <parent link="base_link"/>
    <child link="center_right_wheel_link"/>
    <origin xyz="0.0 -0.26 0.12"/>
    <axis xyz="0 1 0"/>
  </joint>

  <!-- Center Left Wheel -->
  <link name="center_left_wheel_link">
    <visual>
      <geometry>
        <cylinder length="0.14" radius="0.12"/>
      </geometry>
      <material name="light_grey"/>
      <origin rpy="1.5707963267948966 0 0"/>
    </visual>
    <collision>
      <geometry>
        <cylinder length="0.14" radius="0.12"/>
      </geometry>
      <origin rpy="1.5707963267948966 0 0"/>
      <surface>
        <friction>
          <ode>
            <mu>30</mu>
            <mu2>20</mu2>
          </ode>
        </friction>
      </surface>
    </collision>
    <inertial>
      <mass value="2.0"/>
      <inertia ixx="0.0005" ixy="0.0" ixz="0.0" iyy="0.0005" iyz="0.0" izz="0.0003"/>
      <origin xyz="0 0 0"/>
    </inertial>
  </link>
  <joint name="center_left_wheel_joint" type="continuous">
    <parent link="base_link"/>
    <child link="center_left_wheel_link"/>
    <origin xyz="0.0 0.26 0.12"/>
    <axis xyz="0 1 0"/>
  </joint>

  <!-- Rear Right Wheel -->
  <link name="rear_right_wheel_link">
    <visual>
      <geometry>
        <cylinder length="0.14" radius="0.12"/>
      </geometry>
      <material name="light_grey"/>
      <origin rpy="1.5707963267948966 0 0"/>
    </visual>
    <collision>
      <geometry>
        <cylinder length="0.14" radius="0.12"/>
      </geometry>
      <origin rpy="1.5707963267948966 0 0"/>
      <surface>
        <friction>
          <ode>
            <mu>30</mu>
            <mu2>20</mu2>
          </ode>
        </friction>
      </surface>
    </collision>
    <inertial>
      <mass value="2.0"/>
      <inertia ixx="0.0005" ixy="0.0" ixz="0.0" iyy="0.0005" iyz="0.0" izz="0.0003"/>
      <origin xyz="0 0 0"/>
    </inertial>
  </link>
  <joint name="rear_right_wheel_joint" type="continuous">
    <parent link="base_link"/>
    <child link="rear_right_wheel_link"/>
    <origin xyz="-0.5 -0.26 0.12"/>
    <axis xyz="0 1 0"/>
  </joint>

  <!-- Rear Left Wheel -->
  <link name="rear_left_wheel_link">
    <visual>
      <geometry>
        <cylinder length="0.14" radius="0.12"/>
      </geometry>
      <material name="light_grey"/>
      <origin rpy="1.5707963267948966 0 0"/>
    </visual>
    <collision>
      <geometry>
        <cylinder length="0.14" radius="0.12"/>
      </geometry>
      <origin rpy="1.5707963267948966 0 0"/>
      <surface>
        <friction>
          <ode>
            <mu>30</mu>
            <mu2>20</mu2>
          </ode>
        </friction>
      </surface>
    </collision>
    <inertial>
      <mass value="2.0"/>
      <inertia ixx="0.0005" ixy="0.0" ixz="0.0" iyy="0.0005" iyz="0.0" izz="0.0003"/>
      <origin xyz="0 0 0"/>
    </inertial>
  </link>
  <joint name="rear_left_wheel_joint" type="continuous">
    <parent link="base_link"/>
    <child link="rear_left_wheel_link"/>
    <origin xyz="-0.5 0.26 0.12"/>
    <axis xyz="0 1 0"/>
  </joint>

  <!-- Velodyne Lidar -->
  <joint name="velodyne_joint" type="fixed">
    <parent link="base_link"/>
    <child link="velodyne"/>
    <origin xyz="0.4283333333333333 0 0.5375"/>
  </joint>
  <link name="velodyne">
    <visual>
      <origin rpy="0 0 0" xyz="0 0 0"/>
      <geometry>
        <cylinder length="0.05" radius="0.05"/>
      </geometry>
      <material name="red"/>
    </visual>
    <collision>
      <origin rpy="0 0 0" xyz="0.015 0 -0.0065"/>
      <geometry>
        <cylinder length="0.0315" radius="0.055"/>
      </geometry>
    </collision>
    <inertial>
      <mass value="0.114"/>
      <origin xyz="0 0 0"/>
      <inertia ixx="0.0001" ixy="0.0" ixz="0.0" iyy="0.0001" iyz="0.0" izz="0.00005"/>
    </inertial>
  </link>

  <!-- IMU -->
  <joint name="imu_joint" type="fixed">
    <parent link="base_link"/>
    <child link="imu_link"/>
    <origin xyz="0.4283333333333333 0 0.5375"/>
  </joint>
  <link name="imu_link"/>

  <!-- IMU Sensor -->
  <gazebo reference="imu_link">
    <sensor name="tb3_imu" type="imu">
      <always_on>true</always_on>
      <update_rate>200</update_rate>
      <imu>
        <angular_velocity>
          <x>
            <noise type="gaussian">
              <mean>0.0</mean>
              <stddev>2e-4</stddev>
            </noise>
          </x>
          <y>
            <noise type="gaussian">
              <mean>0.0</mean>
              <stddev>2e-4</stddev>
            </noise>
          </y>
          <z>
            <noise type="gaussian">
              <mean>0.0</mean>
              <stddev>2e-4</stddev>
            </noise>
          </z>
        </angular_velocity>
        <linear_acceleration>
          <x>
            <noise type="gaussian">
              <mean>0.0</mean>
              <stddev>1.7e-2</stddev>
            </noise>
          </x>
          <y>
            <noise type="gaussian">
              <mean>0.0</mean>
              <stddev>1.7e-2</stddev>
            </noise>
          </y>
          <z>
            <noise type="gaussian">
              <mean>0.0</mean>
              <stddev>1.7e-2</stddev>
            </noise>
          </z>
        </linear_acceleration>
      </imu>
    </sensor>
  </gazebo>

  <!-- Velodyne Lidar -->
  <gazebo reference="velodyne">
    <sensor name="velodyne" type="gpu_lidar">
      <update_rate>10</update_rate>
      <visualize>true</visualize>
      <always_on>true</always_on>
      <gz_frame_id>velodyne</gz_frame_id>
      <topic>velodyne</topic>
      <lidar>
        <scan>
          <horizontal>
            <samples>512</samples>
            <resolution>1</resolution>
            <min_angle>-3.14159265359</min_angle>
            <max_angle>3.14159265359</max_angle>
          </horizontal>
          <vertical>
            <samples>32</samples>
            <resolution>1</resolution>
            <min_angle>-0.55</min_angle>
            <max_angle>0.26</max_angle>
          </vertical>
        </scan>
        <range>
          <min>0.2</min>
          <max>131.0</max>
          <resolution>0.01</resolution>
        </range>
      </lidar>
    </sensor>
  </gazebo>

  <!-- Gazebo Friction Parameters -->
  <gazebo reference="base_link">
    <mu1>1.0</mu1>
    <mu2>1.0</mu2>
  </gazebo>
  <gazebo reference="front_right_wheel_link">
    <mu1>1.0</mu1>
    <mu2>0.5</mu2>
  </gazebo>
  <gazebo reference="front_left_wheel_link">
    <mu1>1.0</mu1>
    <mu2>0.5</mu2>
  </gazebo>
  <gazebo reference="center_right_wheel_link">
    <mu1>1.0</mu1>
    <mu2>0.5</mu2>
  </gazebo>
  <gazebo reference="center_left_wheel_link">
    <mu1>1.0</mu1>
    <mu2>0.5</mu2>
  </gazebo>
  <gazebo reference="rear_right_wheel_link">
    <mu1>1.0</mu1>
    <mu2>0.5</mu2>
  </gazebo>
  <gazebo reference="rear_left_wheel_link">
    <mu1>1.0</mu1>
    <mu2>0.5</mu2>
  </gazebo>
  <gazebo reference="right_track_link">
    <mu1>0.1</mu1>
    <mu2>0.1</mu2>
  </gazebo>
  <gazebo reference="left_track_link">
    <mu1>0.1</mu1>
    <mu2>0.1</mu2>
  </gazebo>

  <!-- Differential Drive Plugin -->
  <gazebo>
    <plugin filename="gz-sim-diff-drive-system" name="gz::sim::systems::DiffDrive">
      <left_joint>front_left_wheel_joint</left_joint>
      <left_joint>center_left_wheel_joint</left_joint>
      <left_joint>rear_left_wheel_joint</left_joint>
      <right_joint>front_right_wheel_joint</right_joint>
      <right_joint>center_right_wheel_joint</right_joint>
      <right_joint>rear_right_wheel_joint</right_joint>
      <wheel_separation>0.52</wheel_separation>
      <wheel_radius>0.12</wheel_radius>
      <topic>cmd_vel</topic>
      <odom_topic>odom</odom_topic>
      <frame_id>odom</frame_id>
      <tf_topic>/tf</tf_topic>
      <child_frame_id>base_link</child_frame_id>
      <odom_publisher_frequency>100</odom_publisher_frequency>
    </plugin>
  </gazebo>

  <!-- Joint State Publisher -->
  <gazebo>
    <plugin filename="gz-sim-joint-state-publisher-system" name="gz::sim::systems::JointStatePublisher">
      <topic>joint_states</topic>
      <update_rate>30</update_rate>
      <joint_name>front_left_wheel_joint</joint_name>
      <joint_name>front_right_wheel_joint</joint_name>
      <joint_name>center_left_wheel_joint</joint_name>
      <joint_name>center_right_wheel_joint</joint_name>
      <joint_name>rear_left_wheel_joint</joint_name>
      <joint_name>rear_right_wheel_joint</joint_name>
    </plugin>
  </gazebo>

</robot>